<?xml version="1.0"?>
<robot xmlns:xacro="http://www.ros.org/wiki/xacro" name="pan_tilt">

	<xacro:property name="length" value="0.4"/>
	<xacro:property name="radius" value="0.04"/>

	<link name="dummy">
	</link>

	<joint name="dummy_joint" type="fixed">
		<parent link="dummy"/>
		<child link="base_link"/>
	</joint>

	<link name="base_link">
		<visual>
			<geometry>
				<cylinder length="${length}" radius="${radius}"/>
			</geometry>
			<origin rpy="0 0 0" xyz="0 0 0"/>
			<material name="yellow">
				<color rgba="1 1 0 1"/>
			</material>
		</visual>
	</link>

	<joint name="pan_joint" type="revolute"/>
		<child link="pan_link"/>
		<origin xyz="0 0 0.1"/>
		<axis xyz="0 0 1"/>
		<limit effort="300" velocity="0.05" lower="-3.14" upper="3.14"/>
		<dynamics damping="50" friction="1"/>
	</joint>

	<link name="pan_link">
		<visual>
			<geometry> 
				<cylinder length="${length}" radius="${radius}"/>
			</geometry>
			<origin rpy="0 0 0" xyz="0 0 0.09"/>
			<material name="red">
				<color rgba="0 0 1 1"/>
			</material>
		</visual>
	</link>

	<joint name="tilt_joint" type="revolute">
		<parent link="pan_link"/>
		<child link="tilt_link"/>
		<origin xyz="0 0 0.2"/>
		<axis xyz="0 1 0"/>
		<limit effort="300" velocity="0.05" lower="-4.64" upper="-1.5"/>
		<dynamics damping="50" friction="1"/>
	</joint>

	<link name="tilt_link">
		<visual>
			<geometry>
				<cylinder length="0.4" radius="0.04"/>
			</geometry>
			<origin rpy="0 1.5 0" xyz="0 0 0 "/>
			<material name="green">
				<color rgba="1 0 0 1"/>
			</material>
		</visual>
	</link>
